<robot name="omnidirectional_robot" xmlns:xacro="http://www.ros.org/wiki/xacro">
    <!-- ベースリンク -->
    <link name="base_link">
        <visual>
            <geometry>
                <cylinder radius="0.15" length="0.02" />
            </geometry>
            <material name="gray">
                <color rgba="0.2 0.2 0.2 1" />
            </material>
        </visual>
        <collision>
            <geometry>
                <cylinder radius="0.15" length="0.02" />
            </geometry>
        </collision>
        <inertial>
            <mass value="5.0" />
            <inertia ixx="0.1" ixy="0" ixz="0" iyy="0.1" iyz="0" izz="0.2" />
        </inertial>
    </link>

    <!-- wheel -->
    <link name="wheel_1">
        <inertial>
            <mass value="2" />
            <inertia ixx="1e-3" ixy="0.0" ixz="0" iyy="1e-3" iyz="0" izz="1e-3" />
        </inertial>
        <visual>
            <geometry>
                <cylinder radius="0.05" length="0.02" />
            </geometry>
            <material name="whtie">
                <color rgba="1 1 1 1" />
            </material>
        </visual>
        <collision>
            <geometry>
                <cylinder radius="0.05" length="0.02" />
            </geometry>
            <contact_coefficients mu="1" kp="1e+13" kd="1.0" />
        </collision>
    </link>
    <joint name="wheel_1_joint" type="continuous">
        <origin xyz="0.15 0 0.0" rpy="1.57 0.0 1.57" />
        <parent link="base_link" />
        <child link="wheel_1" />
        <axis xyz="0.0 0.0 1.0" />
    </joint>

    <link name="wheel_2">
        <inertial>
            <mass value="2" />
            <inertia ixx="1e-3" ixy="0.0" ixz="0" iyy="1e-3" iyz="0" izz="1e-3" />
        </inertial>
        <visual>
            <geometry>
                <cylinder radius="0.05" length="0.02" />
            </geometry>
            <material name="whtie">
                <color rgba="1 1 1 1" />
            </material>
        </visual>
        <collision>
            <geometry>
                <cylinder radius="0.05" length="0.02" />
            </geometry>
            <contact_coefficients mu="1" kp="1e+13" kd="1.0" />
        </collision>
    </link>
    <joint name="wheel_2_joint" type="continuous">
        <origin xyz="-0.106 0.106 0" rpy="1.57 0.0 0.785398" />
        <parent link="base_link" />
        <child link="wheel_2" />
        <axis xyz="0.0 0.0 1.0" />
    </joint>

    <link name="wheel_3">
        <inertial>
            <mass value="2" />
            <inertia ixx="1e-3" ixy="0.0" ixz="0" iyy="1e-3" iyz="0" izz="1e-3" />
        </inertial>
        <visual>
            <geometry>
                <cylinder radius="0.05" length="0.02" />
            </geometry>
            <material name="whtie">
                <color rgba="1 1 1 1" />
            </material>
        </visual>
        <collision>
            <geometry>
                <cylinder radius="0.05" length="0.02" />
            </geometry>
            <contact_coefficients mu="1" kp="1e+13" kd="1.0" />
        </collision>
    </link>
    <joint name="wheel_3_joint" type="continuous">
        <origin xyz="-0.106 -0.106 0" rpy="1.57 0.0 -0.785398" />
        <parent link="base_link" />
        <child link="wheel_3" />
        <axis xyz="0.0 0.0 1.0" />
    </joint>

    <gazebo>
        <plugin filename="libgazebo_ros2_control.so" name="gazebo_ros2_control">
            <parameters>/home/ros2/ros_ws/src/inrof2025_ros/config/jtc.yaml</parameters>
        </plugin>
    </gazebo>

    <ros2_control name="GazeboSystem" type="system">
        <hardware>
        <plugin>gazebo_ros2_control/GazeboSystem</plugin>
        </hardware>

        <joint name="wheel_1_joint">
            <command_interface name="velocity"/>
            <state_interface name="position"/>
            <state_interface name="velocity"/>
        </joint>
        <joint name="wheel_2_joint">
            <command_interface name="velocity"/>
            <state_interface name="position"/>
            <state_interface name="velocity"/>
        </joint>
        <joint name="wheel_3_joint">
            <command_interface name="velocity"/>
            <state_interface name="velocity"/>
            <param name="initial_position">0.0</param>   
        </joint>
    </ros2_control>

    <!-- <ros2_control name="GazeboSystem" type="system">
        <hardware>gazebo_ros2_control/GazeboSystem</hardware>
        <joint name="wheel_1_joint">
            <command_interface name="velocity"/>
            <state_interface name="position"/>
            <state_interface name="velocity"/>
        </joint>
        <joint name="wheel_2_joint">
            <command_interface name="velocity"/>
            <state_interface name="position"/>
            <state_interface name="velocity"/>
        </joint>
        <joint name="wheel_3_joint">
            <command_interface name="velocity"/>
            <state_interface name="velocity"/>
            <param name="initial_position">0.0</param>   
        </joint>
    </ros2_control> -->

</robot>