<robot name="omnidirectional_robot" xmlns:xacro="http://www.ros.org/wiki/xacro">
    <!-- ベースリンク -->
    <link name="base_link">
        <visual>
            <geometry>
                <cylinder radius="0.15" length="0.02" />
            </geometry>
            <material name="gray">
                <color rgba="0.2 0.2 0.2 1" />
            </material>
        </visual>
        <collision>
            <geometry>
                <cylinder radius="0.15" length="0.02" />
            </geometry>
        </collision>
        <inertial>
            <mass value="5.0" />
            <inertia ixx="0.1" ixy="0" ixz="0" iyy="0.1" iyz="0" izz="0.2" />
        </inertial>
    </link>

    <link name="base_footprint"/>
    <joint name="base_joint" type="fixed">
        <parent link="base_footprint"/>
        <child link="base_link"/>
        <origin xyz="0.0 0.0 0.03" rpy="0 0 0"/>
    </joint>

    <!-- wheel -->
    <link name="wheel_1">
        <inertial>
            <mass value="2" />
            <inertia ixx="1e-3" ixy="0.0" ixz="0" iyy="1e-3" iyz="0" izz="1e-3" />
        </inertial>
        <visual>
            <geometry>
                <cylinder radius="0.03" length="0.02" />
            </geometry>
            <material name="whtie">
                <color rgba="1 1 1 1" />
            </material>
        </visual>
        <collision>
            <geometry>
                <cylinder radius="0.03" length="0.02" />
            </geometry>
            <contact_coefficients mu="3" kp="1e+13" kd="1.0" />
        </collision>
        <gazebo reference="wheel_1">
            <mu2>0.0</mu2>
        </gazebo>
    </link>
    <joint name="wheel_1_joint" type="continuous">
        <!-- <origin xyz="0.15 0 0.0" rpy="1.57 0.0 1.57" /> -->
        <origin xyz="0.075 0.12990381056 0" rpy="1.57 0.0 -0.5235987755983" />
        <parent link="base_link" />
        <child link="wheel_1" />
        <axis xyz="0.0 0.0 1.0" />
    </joint>

    <link name="wheel_2">
        <inertial>
            <mass value="2" />
            <inertia ixx="1e-3" ixy="0.0" ixz="0" iyy="1e-3" iyz="0" izz="1e-3" />
        </inertial>
        <visual>
            <geometry>
                <cylinder radius="0.03" length="0.02" />
            </geometry>
            <material name="whtie">
                <color rgba="1 1 1 1" />
            </material>
        </visual>
        <collision>
            <geometry>
                <cylinder radius="0.03" length="0.02" />
            </geometry>
            <contact_coefficients mu="3" kp="1e+13" kd="1.0" />
        </collision>
        <gazebo reference="wheel_1">
            <mu2>0.0</mu2>
        </gazebo>
    </link>
    <joint name="wheel_2_joint" type="continuous">
        <origin xyz="-0.15 0 0.0" rpy="1.57 0.0 1.57" />
        <!-- <origin xyz="-0.075 0.12990381056 0" rpy="1.57 0.0 0.5235987755983" /> -->
        <parent link="base_link" />
        <child link="wheel_2" />
        <axis xyz="0.0 0.0 1.0" />
    </joint>

    <link name="wheel_3">
        <inertial>
            <mass value="2" />
            <inertia ixx="1e-3" ixy="0.0" ixz="0" iyy="1e-3" iyz="0" izz="1e-3" />
        </inertial>
        <visual>
            <geometry>
                <cylinder radius="0.03" length="0.02" />
            </geometry>
            <material name="whtie">
                <color rgba="1 1 1 1" />
            </material>
        </visual>
        <collision>
            <geometry>
                <cylinder radius="0.03" length="0.02" />
            </geometry>
            <contact_coefficients mu="3" kp="1e+13" kd="1.0" />
        </collision>
        <gazebo reference="wheel_1">
            <mu2>0.0</mu2>
        </gazebo>
    </link>
    <joint name="wheel_3_joint" type="continuous">
        <origin xyz="0.075 -0.12990381056 0" rpy="1.57 0.0 -2.6179938779915" />
        <parent link="base_link" />
        <child link="wheel_3" />
        <axis xyz="0.0 0.0 1.0"/>
    </joint>

    <!-- lidar settings -->
    <link name="base_laser">
        <inertial>
            <mass value="0.5" />
            <inertia ixx="0.01" ixy="0.0" ixz="0" iyy="0.01" iyz="0" izz="0.01" />
        </inertial>
        <visual>
            <geometry>
                <cylinder radius="0.05" length="0.05" />
            </geometry>
            <material name="red">
                <color rgba="1 0 0 0.7" />
            </material>
        </visual>
    </link>

    <joint name="lidar_joint" type="fixed">
        <origin xyz="0.15 0 0" rpy="0 0 0" />
        <parent link="base_link" />
        <child link="base_laser" />
    </joint>

    <gazebo reference="base_laser">
        <sensor name="gazebo_lidar" type="ray">
            <always_on>true</always_on>
            <visualize>true</visualize>
            <update_rate>60</update_rate>
            <plugin filename="libgazebo_ros_ray_sensor.so" name="gazebo_lidar">
                <ros>
                    <remapping>~/out:=scan</remapping>
                </ros>
                <output_type>sensor_msgs/LaserScan</output_type>
                <frame_name>base_laser</frame_name>
            </plugin>
            <ray>
                <scan>
                    <horizontal>
                        <samples>360</samples>
                        <resolution>1.000000</resolution>
                        <min_angle>-1.570000</min_angle>
                        <max_angle>1.570000</max_angle>
                    </horizontal>
                </scan>
                <range>
                    <min>0.020</min>
                    <max>12.0</max>
                    <resolution>0.015</resolution>
                </range>
                <noise>
                    <type>gaussian</type>
                    <mean>0.0</mean>
                    <stddev>0.01</stddev>
                </noise>
            </ray>
        </sensor>
        <material>Gazebo/DarkGrey</material>
    </gazebo>

    <gazebo>
        <plugin filename="libgazebo_ros2_control.so" name="gazebo_ros2_control">
            <parameters>/home/ros2/ros_ws/src/inrof2025_ros/config/jtc.yaml</parameters>
        </plugin>
    </gazebo>

    <plugin name="gazebo_ros_state" filename="libgazebo_ros_state.so">
      <ros>
        <namespace>/gazebo</namespace>
      </ros>

      <update_rate>1.0</update_rate>
    </plugin>

    <!-- ros2_control_settings -->
    <ros2_control name="GazeboSystem" type="system">
        <hardware>
            <plugin>gazebo_ros2_control/GazeboSystem</plugin>
        </hardware>

        <joint name="wheel_1_joint">
            <param name="vel_kp">1</param>
            <param name="vel_kd">0.0001</param>
            <param name="vel_ki">0.0001</param>
            <param name="vel_max_integral_error">100</param>
            <param name="vel_min_integral_error">-100</param>
            <command_interface name="velocity_pid" />
            <state_interface name="position" />
            <state_interface name="velocity" />
        </joint>
        <joint name="wheel_2_joint">
            <param name="vel_kp">1</param>
            <param name="vel_kd">0.0001</param>
            <param name="vel_ki">0.0001</param>
            <param name="vel_max_integral_error">100</param>
            <param name="vel_min_integral_error">-100</param>
            <command_interface name="velocity_pid" />
            <state_interface name="position" />
            <state_interface name="velocity" />
        </joint>
        <joint name="wheel_3_joint">
            <param name="vel_kp">1</param>
            <param name="vel_kd">0.0001</param>
            <param name="vel_ki">0.0001</param>
            <param name="vel_max_integral_error">100</param>
            <param name="vel_min_integral_error">-100</param>
            <command_interface name="velocity_pid" />
            <state_interface name="position" />
            <state_interface name="velocity" />
        </joint>
    </ros2_control>
</robot>